Workbook

Sheet 자료입력페이지
A1: 세금계산서 자동계산발행 (자료입력화면)
B3: 공급자 정보입력 | G3: 공급받는자 정보입력
B5: 상호 | C5: 스타트코딩 | G5: 상호 | H5: 놀부전자
B6: 사업자등록번호 | C6: 111-11-11111 | G6: 사업자등록번호 | H6: 222-22-222222
B7: 대표자성명 | C7: 스타트코딩 | G7: 대표자성명 | H7: 놀부
B8: 주소 | C8: 서울시 서초구 서초동 123 | G8: 주소 | H8: 서울시 강남구 삼성동 123
B9: 업태 | C9: 인터넷서비스 | G9: 업태 | H9: 제조
B10: 종목 | C10: 온라인정보제공 | G10: 종목 | H10: 부품제조
G11: 비고
B12: 품목자료입력
F13: * 본 계산식은 공급가액에서 부가세 10% 추가형식(+)
B14: 작성일자(발행) | C14: 44927
C15: 품목 | D15: 규격 | E15: 수량 | F15: 단가 | G15: 공급가액 | H15: 부가세 | I15: 발행금액
B16: 품목 1 | C16: ERP 프로그램 | E16: 1 | F16: 250000 | G16: =(E16*F16) -> 250000 | H16: =(G16/10) -> 25000 | I16: =(G16+H16) -> 275000
B17: 품목 2 | C17: 서버유지보수 | E17: 1 | F17: 100000 | G17: =(E17*F17) -> 100000 | H17: =(G17/10) -> 10000 | I17: =(G17+H17) -> 110000
B18: 품목 3 | G18: =(E18*F18) -> 0 | H18: =(G18/10) -> 0 | I18: =(G18+H18) -> 0
B19: 품목 4 | G19: =(E19*F19) -> 0 | H19: =(G19/10) -> 0 | I19: =(G19+H19) -> 0
B20: 품목 5 | G20: =(E20*F20) -> 0 | H20: =(G20/10) -> 0 | I20: =(G20+H20) -> 0
B21: 합계금액 | G21: =SUM(G16:G20) -> 350000 | H21: =SUM(H16:H20) -> 35000 | I21: =SUM(I16:I20) -> 385000
B23: 책번호,일련번호입력
B25: 책번호 | C25: 02 | D25: 권 | E25: 11 | F25: 호
B26: 일련번호 | C26: 32-345
C29: 부분은 사용자가 입력할 부분임 (나머지는 자동계산됨)
B31: * 입력하신 내용의 세금계산서 출력페이지는 아래 시트지 "세금계산서 출력페이지" 부분에서 있습니다.

Sheet 세금계산서 출력페이지
A1: 세금계산서 자동계산발행 (세금계산서출력화면) | AG1: 1
A2: [별지 제11호 서식]
A3: 세 금 계 산 서 (공급받는자보관용) | W3: 책 번 호 | AA3: =자료입력페이지!C25 -> 02 | AC3: 권 | AD3: =자료입력페이지!E25 -> 11 | AF3: 호
W4: 일 련 번 호 | AA4: =MID(자료입력페이지!C26,1,1) -> 3 | AB4: =MID(자료입력페이지!C26,2,1) -> 2 | AC4: =MID(자료입력페이지!C26,3,1) -> - | AD4: =MID(자료입력페이지!C26,4,1) -> 3 | AE4: =MID(자료입력페이지!C26,5,1) -> 4 | AF4: =MID(자료입력페이지!C26,6,1) -> 5
A5: 공 급 자 | B5: 등록번호 | E5: =MID(자료입력페이지!C6,1,1) -> 1 | F5: =MID(자료입력페이지!C6,2,1) -> 1 | G5: =MID(자료입력페이지!C6,3,1) -> 1 | H5: - | I5: =MID(자료입력페이지!C6,5,1) -> 1 | J5: =MID(자료입력페이지!C6,6,1) -> 1 | K5: - | L5: =MID(자료입력페이지!C6,8,1) -> 1 | M5: =MID(자료입력페이지!C6,9,1) -> 1 | N5: =MID(자료입력페이지!C6,10,1) -> 1 | O5: =MID(자료입력페이지!C6,11,1) -> 1 | P5: =MID(자료입력페이지!C6,12,1) -> 1 | Q5: 공급받는자 | R5: 등록번호 | U5: =MID(자료입력페이지!H6,1,1) -> 2 | V5: =MID(자료입력페이지!H6,2,1) -> 2 | W5: =MID(자료입력페이지!H6,3,1) -> 2 | X5: - | Y5: =MID(자료입력페이지!H6,5,1) -> 2 | Z5: =MID(자료입력페이지!H6,6,1) -> 2 | AA5: - | AB5: =MID(자료입력페이지!H6,8,1) -> 2 | AC5: =MID(자료입력페이지!H6,9,1) -> 2 | AD5: =MID(자료입력페이지!H6,10,1) -> 2 | AE5: =MID(자료입력페이지!H6,11,1) -> 2 | AF5: =MID(자료입력페이지!H6,12,1) -> 2
B7: 상 호 | E7: =자료입력페이지!C5 -> 스타트코딩 | K7: 성명 | L7: =자료입력페이지!C7 -> 스타트코딩 | P7: 인 | R7: 상 호 | U7: =자료입력페이지!H5 -> 놀부전자 | AA7: 성명 | AB7: =자료입력페이지!H7 -> 놀부 | AF7: 인
B8: (법인명) | R8: (법인명)
B9: 사 업 장 | E9: =자료입력페이지!C8 -> 서울시 서초구 서초동 123 | R9: 사 업 장 | U9: =자료입력페이지!H8 -> 서울시 강남구 삼성동 123
B10: 주 소 | R10: 주 소
B11: 업 태 | E11: =자료입력페이지!C9 -> 인터넷서비스 | K11: 종목 | L11: =자료입력페이지!C10 -> 온라인정보제공 | R11: 업 태 | U11: =자료입력페이지!H9 -> 제조 | AA11: 종목 | AB11: =자료입력페이지!H10 -> 부품제조
A13: 작 성 | E13: 공 급 가 액 | R13: 세 액 | AB13: 비 고
A14: 년 | C14: 월 | D14: 일 | E14: 공란수 | G14: 백 | H14: 십 | I14: 억 | J14: 천 | K14: 백 | L14: 십 | M14: 만 | N14: 천 | O14: 백 | P14: 십 | Q14: 일 | R14: 십 | S14: 억 | T14: 천 | U14: 백 | V14: 십 | W14: 만 | X14: 천 | Y14: 백 | Z14: 십 | AA14: 일 | AB14: =자료입력페이지!H11 -> 0
A15: =YEAR(자료입력페이지!C14) -> 2023 | C15: =MONTH(자료입력페이지!C14) -> 1 | D15: =DAY(자료입력페이지!C14) -> 1 | E15: =COUNTBLANK(G15:Q15) -> 5 | G15: =IF(ISERROR(MID(자료입력페이지!G21,LEN(자료입력페이지!G21)-10,1)),"",MID(자료입력페이지!G21,LEN(자료입력페이지!G21)-10,1)) | H15: =IF(ISERROR(MID(자료입력페이지!G21,LEN(자료입력페이지!G21)-9,1)),"",MID(자료입력페이지!G21,LEN(자료입력페이지!G21)-9,1)) | I15: =IF(ISERROR(MID(자료입력페이지!G21,LEN(자료입력페이지!G21)-8,1)),"",MID(자료입력페이지!G21,LEN(자료입력페이지!G21)-8,1)) | J15: =IF(ISERROR(MID(자료입력페이지!G21,LEN(자료입력페이지!G21)-7,1)),"",MID(자료입력페이지!G21,LEN(자료입력페이지!G21)-7,1)) | K15: =IF(ISERROR(MID(자료입력페이지!G21,LEN(자료입력페이지!G21)-6,1)),"",MID(자료입력페이지!G21,LEN(자료입력페이지!G21)-6,1)) | L15: =IF(ISERROR(MID(자료입력페이지!G21,LEN(자료입력페이지!G21)-5,1)),"",MID(자료입력페이지!G21,LEN(자료입력페이지!G21)-5,1)) -> 3 | M15: =IF(ISERROR(MID(자료입력페이지!G21,LEN(자료입력페이지!G21)-4,1)),"",MID(자료입력페이지!G21,LEN(자료입력페이지!G21)-4,1)) -> 5 | N15: =IF(ISERROR(MID(자료입력페이지!G21,LEN(자료입력페이지!G21)-3,1)),"",MID(자료입력페이지!G21,LEN(자료입력페이지!G21)-3,1)) -> 0 | O15: =IF(ISERROR(MID(자료입력페이지!G21,LEN(자료입력페이지!G21)-2,1)),"",MID(자료입력페이지!G21,LEN(자료입력페이지!G21)-2,1)) -> 0 | P15: =IF(ISERROR(MID(자료입력페이지!G21,LEN(자료입력페이지!G21)-1,1)),"",MID(자료입력페이지!G21,LEN(자료입력페이지!G21)-1,1)) -> 0 | Q15: =RIGHT(자료입력페이지!G21) -> 0 | R15: =IF(ISERROR(MID(자료입력페이지!H21,LEN(자료입력페이지!H21)-9,1)),"",MID(자료입력페이지!H21,LEN(자료입력페이지!H21)-9,1)) | S15: =IF(ISERROR(MID(자료입력페이지!H21,LEN(자료입력페이지!H21)-8,1)),"",MID(자료입력페이지!H21,LEN(자료입력페이지!H21)-8,1)) | T15: =IF(ISERROR(MID(자료입력페이지!H21,LEN(자료입력페이지!H21)-7,1)),"",MID(자료입력페이지!H21,LEN(자료입력페이지!H21)-7,1)) | U15: =IF(ISERROR(MID(자료입력페이지!H21,LEN(자료입력페이지!H21)-6,1)),"",MID(자료입력페이지!H21,LEN(자료입력페이지!H21)-6,1)) | V15: =IF(ISERROR(MID(자료입력페이지!H21,LEN(자료입력페이지!H21)-5,1)),"",MID(자료입력페이지!H21,LEN(자료입력페이지!H21)-5,1)) | W15: =IF(ISERROR(MID(자료입력페이지!H21,LEN(자료입력페이지!H21)-4,1)),"",MID(자료입력페이지!H21,LEN(자료입력페이지!H21)-4,1)) -> 3 | X15: =IF(ISERROR(MID(자료입력페이지!H21,LEN(자료입력페이지!H21)-3,1)),"",MID(자료입력페이지!H21,LEN(자료입력페이지!H21)-3,1)) -> 5 | Y15: =IF(ISERROR(MID(자료입력페이지!H21,LEN(자료입력페이지!H21)-2,1)),"",MID(자료입력페이지!H21,LEN(자료입력페이지!H21)-2,1)) -> 0 | Z15: =IF(ISERROR(MID(자료입력페이지!H21,LEN(자료입력페이지!H21)-1,1)),"",MID(자료입력페이지!H21,LEN(자료입력페이지!H21)-1,1)) -> 0 | AA15: =RIGHT(자료입력페이지!H21) -> 0
A16: 월 | B16: 일 | C16: 품 목 | I16: 규격 | L16: 수량 | O16: 단 가 | T16: 공 급 가 액 | Z16: 세 액 | AE16: 비고
A17: =C15 -> 1 | B17: =D15 -> 1 | C17: =자료입력페이지!C16 -> ERP 프로그램 | I17: =자료입력페이지!D16 -> 0 | L17: =자료입력페이지!E16 -> 1 | O17: =자료입력페이지!F16 -> 250000 | T17: =자료입력페이지!G16 -> 250000 | Z17: =자료입력페이지!H16 -> 25000
C18: =자료입력페이지!C17 -> 서버유지보수 | I18: =자료입력페이지!D17 -> 0 | L18: =자료입력페이지!E17 -> 1 | O18: =자료입력페이지!F17 -> 100000 | T18: =자료입력페이지!G17 -> 100000 | Z18: =자료입력페이지!H17 -> 10000
C19: =자료입력페이지!C18 -> 0 | I19: =자료입력페이지!D18 -> 0 | L19: =자료입력페이지!E18 -> 0 | O19: =자료입력페이지!F18 -> 0 | T19: =자료입력페이지!G18 -> 0 | Z19: =자료입력페이지!H18 -> 0
C20: =자료입력페이지!C19 -> 0 | I20: =자료입력페이지!D20 -> 0 | L20: =자료입력페이지!E19 -> 0 | O20: =자료입력페이지!F19 -> 0 | T20: =자료입력페이지!G19 -> 0 | Z20: =자료입력페이지!H19 -> 0
C21: =자료입력페이지!C20 -> 0 | L21: =자료입력페이지!E20 -> 0 | O21: =자료입력페이지!F20 -> 0 | T21: =자료입력페이지!G20 -> 0 | Z21: =자료입력페이지!H20 -> 0
A22: 합계금액 | F22: 현 금 | K22: 수 표 | P22: 어 음 | U22: 외상미수금 | Z22: 이 금액을 | AD22: =IF(AG1=1,"영수","청구") -> 영수 | AF22: 함
A23: =자료입력페이지!I21 -> 385000
A24: 22226-28131일 '96.3.27승인 | U24: 인쇄용지(특급)34g/m2 182mmx128mm
A28: [별지 제11호 서식]
A29: 세 금 계 산 서 (공급자보관용) | W29: 책 번 호 | AA29: =AA3 -> 02 | AC29: 권 | AD29: =AD3 -> 11 | AF29: 호
W30: 일 련 번 호 | AA30: =AA4 -> 3 | AB30: =AB4 -> 2 | AC30: =AC4 -> - | AD30: =AD4 -> 3 | AE30: =AE4 -> 4 | AF30: =AF4 -> 5
A31: 공 급 자 | B31: 등록번호 | E31: =E5 -> 1 | F31: =F5 -> 1 | G31: =G5 -> 1 | H31: =H5 -> - | I31: =I5 -> 1 | J31: =J5 -> 1 | K31: =K5 -> - | L31: =L5 -> 1 | ... P31: =P5 -> 1 | Q31: 공급받는자 | R31: 등록번호 | U31: =U5 -> 2 | V31: =V5 -> 2 | W31: =W5 -> 2 | X31: - | Y31: =Y5 -> 2 | Z31: =Z5 -> 2 | AA31: - | AB31: =AB5 -> 2 | AC31: =AC5 -> 2 | AD31: =AD5 -> 2 | AE31: =AE5 -> 2 | AF31: =AF5 -> 2
B33: 상 호 | E33: =E7 -> 스타트코딩 | K33: 성명 | L33: =L7 -> 스타트코딩 | P33: 인 | R33: 상 호 | U33: =U7 -> 놀부전자 | AA33: 성명 | AB33: =AB7 -> 놀부 | AF33: 인
B34: (법인명) | R34: (법인명)
B35: 사 업 장 | E35: =E9 -> 서울시 서초구 서초동 123 | R35: 사 업 장 | U35: =U9 -> 서울시 강남구 삼성동 123
B36: 주 소 | R36: 주 소
B37: 업 태 | E37: =E11 -> 인터넷서비스 | K37: 종목 | L37: =L11 -> 온라인정보제공 | R37: 업 태 | U37: =U11 -> 제조 | AA37: 종목 | AB37: =AB11 -> 부품제조
A39: 작 성 | E39: 공 급 가 액 | R39: 세 액 | AB39: 비 고
A40: 년 | C40: 월 | D40: 일 | E40: 공란수 | G40: 백 | H40: 십 | I40: 억 | J40: 천 | K40: 백 | L40: 십 | M40: 만 | N40: 천 | O40: 백 | P40: 십 | Q40: 일 | R40: 십 | S40: 억 | T40: 천 | U40: 백 | V40: 십 | W40: 만 | X40: 천 | Y40: 백 | Z40: 십 | AA40: 일 | AB40: =AB14 -> 0
A41: =A15 -> 2023 | C41: =C15 -> 1 | D41: =D15 -> 1 | E41: =E15 -> 5 | G41: =G15 | H41: =H15 | I41: =I15 | J41: =J15 | K41: =K15 | L41: =L15 -> 3 | M41: =M15 -> 5 | N41: =N15 -> 0 | ... AA41: =AA15 -> 0
A42: 월 | B42: 일 | C42: 품 목 | I42: 규격 | L42: 수량 | O42: 단 가 | T42: 공 급 가 액 | Z42: 세 액 | AE42: 비고
A43: =A17 -> 1 | B43: =B17 -> 1 | C43: =C17 -> ERP 프로그램 | I43: =I17 -> 0 | L43: =L17 -> 1 | O43: =O17 -> 250000 | T43: =T17 -> 250000 | Z43: =Z17 -> 25000
A44: =A18 -> 0 | B44: =B18 -> 0 | C44: =C18 -> 서버유지보수 | I44: =I18 -> 0 | L44: =L18 -> 1 | O44: =O18 -> 100000 | T44: =T18 -> 100000 | Z44: =Z18 -> 10000
A45: =A19 -> 0 | B45: =B19 -> 0 | C45: =C19 -> 0 | I45: =I19 -> 0 | L45: =L19 -> 0 | O45: =O19 -> 0 | T45: =T19 -> 0 | Z45: =Z19 -> 0
C46: =C20 -> 0 | L46: =L20 -> 0 | O46: =O20 -> 0 | T46: =T20 -> 0 | Z46: =Z20 -> 0
A47: =A20 -> 0 | B47: =B20 -> 0 | C47: =C21 -> 0 | I47: =I20 -> 0 | L47: =L21 -> 0 | O47: =O21 -> 0 | T47: =T21 -> 0 | Z47: =Z21 -> 0
...
